Traceback (most recent call last):
  File "/home/jegan/openshift-1317oct-2025/Day4/python-with-mysql/venv/lib/python3.13/site-packages/pymysql/connections.py", line 661, in connect
    sock = socket.create_connection(
        (self.host, self.port), self.connect_timeout, **kwargs
    )
  File "/usr/lib/python3.13/socket.py", line 840, in create_connection
    for res in getaddrinfo(host, port, 0, SOCK_STREAM):
               ~~~~~~~~~~~^^^^^^^^^^^^^^^^^^^^^^^^^^^^
  File "/usr/lib/python3.13/socket.py", line 977, in getaddrinfo
    for res in _socket.getaddrinfo(host, port, family, type, proto, flags):
               ~~~~~~~~~~~~~~~~~~~^^^^^^^^^^^^^^^^^^^^^^^^^^^^^^^^^^^^^^^^
socket.gaierror: [Errno -3] Temporary failure in name resolution

During handling of the above exception, another exception occurred:

Traceback (most recent call last):
  File "/home/jegan/openshift-1317oct-2025/Day4/python-with-mysql/app.py", line 51, in <module>
    init_db()
    ~~~~~~~^^
  File "/home/jegan/openshift-1317oct-2025/Day4/python-with-mysql/app.py", line 24, in init_db
    conn = getConnection()
  File "/home/jegan/openshift-1317oct-2025/Day4/python-with-mysql/app.py", line 13, in getConnection
    return pymysql.connect(
           ~~~~~~~~~~~~~~~^
       host=DB_HOST,
       ^^^^^^^^^^^^^
    ...<4 lines>...
       autocommit=True
       ^^^^^^^^^^^^^^^
    )
    ^
  File "/home/jegan/openshift-1317oct-2025/Day4/python-with-mysql/venv/lib/python3.13/site-packages/pymysql/connections.py", line 365, in __init__
    self.connect()
    ~~~~~~~~~~~~^^
  File "/home/jegan/openshift-1317oct-2025/Day4/python-with-mysql/venv/lib/python3.13/site-packages/pymysql/connections.py", line 723, in connect
    raise exc
pymysql.err.OperationalError: (2003, "Can't connect to MySQL server on 'mysql' ([Errno -3] Temporary failure in name resolution)")
